<?xml version='1.0'?>

<robot name="new_robot" xmlns:xacro="http://www.ros.org/wiki/xacro">

  <xacro:include filename="$(find where_am_i)/urdf/new_robot.gazebo" />

  <link name="robot_footprint"></link>



  <joint name="robot_footprint_joint" type="fixed">

    <origin xyz="0 0 0" rpy="0 0 0" />

    <parent link="robot_footprint"/>

    <child link="chassis" />

  </joint>



  <link name='chassis'>

    <pose>0 0 0.05 0 0 0</pose>



    <inertial>

      <mass value="18.0"/>

      <origin xyz="0.0 0 0" rpy=" 0 0 0"/>

      <inertia

          ixx="0.021" ixy="0" ixz="0"

          iyy="0.076" iyz="0"

          izz="0.093"

      />

    </inertial>



    <collision name='collision'>

      <origin xyz="0 0 0" rpy=" 0 0 0"/> 

      <geometry>

        <box size="0.3 0.15 0.05"/>

      </geometry>

    </collision>



    <visual name='chassis_visual'>

      <origin xyz="0 0 0" rpy=" 0 0 0"/>

      <geometry>

        <box size="0.3 0.15 0.05"/>

      </geometry>

    </visual>



  </link>



  <link name="front_left_wheel">

      <inertial>

          <origin xyz="0.0 0.0 0.0" rpy="0.0 1.5707 1.5707"/>

          <mass value="4.0"/>

          <inertia ixx="0.1" ixy="0.0" ixz="0.0" iyy="0.1" iyz="0.0" izz="0.1"/>

      </inertial>

      <visual name="front_left_wheel_visual">

          <origin xyz="0.0 0.0 0.0" rpy="0.0 1.5707 1.5707"/>

          <geometry>

              <cylinder radius="0.05" length="0.05"/>

          </geometry>

      </visual>

      <collision>

          <origin xyz="0.0 0.0 0.0" rpy="0.0 1.5707 1.5707"/>

          <geometry>

              <cylinder radius="0.05" length="0.05"/>

          </geometry>
          
       <surface>
        <friction>
          <fdir1>1 0 0</fdir1>
          <kp>1000000.0</kp> <!-- kp and kd for rubber -->
          <kd>100.0</kd>
          <mu>1</mu>
          <mu2>1</mu2>
          <slip1>0.5</slip1>
          <slip2>0</slip2>
        </friction>
      </surface>

      </collision>

  </link>



  <joint type="continuous" name="front_left_wheel_hinge">

    <origin xyz="0.1 0.12 0" rpy="0 0 0"/>

    <child link="front_left_wheel"/>

    <parent link="chassis"/>

    <axis xyz="0 1 0" rpy="0 0 0"/>

    <limit effort="10000" velocity="1000"/>

    <dynamics damping="1.0" friction="1.0"/>

  </joint>



  <link name="back_left_wheel">

      <inertial>

          <origin xyz="0.0 0.0 0.0" rpy="0.0 1.5707 1.5707"/>

          <mass value="4.0"/>

          <inertia ixx="0.1" ixy="0.0" ixz="0.0" iyy="0.1" iyz="0.0" izz="0.1"/>

      </inertial>

      <visual name="back_left_wheel_visual">

          <origin xyz="0.0 0.0 0.0" rpy="0.0 1.5707 1.5707"/>

          <geometry>

              <cylinder radius="0.05" length="0.05"/>

          </geometry>

      </visual>

      <collision>

          <origin xyz="0.0 0.0 0.0" rpy="0.0 1.5707 1.5707"/>

          <geometry>

              <cylinder radius="0.05" length="0.05"/>

          </geometry>
          
      <surface>
        <friction>
          <fdir1>1 0 0</fdir1>
          <kp>1000000.0</kp> <!-- kp and kd for rubber -->
          <kd>100.0</kd>
          <mu>1</mu>
          <mu2>1</mu2>
          <slip1>0.5</slip1>
          <slip2>0</slip2>
        </friction>
      </surface>

      </collision>

  </link>



  <joint type="continuous" name="back_left_wheel_hinge">

    <origin xyz="-0.1 0.12 0" rpy="0 0 0"/>

    <child link="back_left_wheel"/>

    <parent link="chassis"/>

    <axis xyz="0 1 0" rpy="0 0 0"/>

    <limit effort="10000" velocity="1000"/>

    <dynamics damping="1.0" friction="1.0"/>

  </joint>



  <link name="front_right_wheel">

      <inertial>

          <origin xyz="0.0 0.0 0.0" rpy="0.0 1.5707 1.5707"/>

          <mass value="4.0"/>

          <inertia ixx="0.1" ixy="0.0" ixz="0.0" iyy="0.1" iyz="0.0" izz="0.1"/>

      </inertial>

      <visual name="front_right_wheel_visual">

          <origin xyz="0.0 0.0 0.0" rpy="0.0 1.5707 1.5707"/>

          <geometry>

              <cylinder radius="0.05" length="0.05"/>

          </geometry>

      </visual>

      <collision>

          <origin xyz="0.0 0.0 0.0" rpy="0.0 1.5707 1.5707"/>

          <geometry>

              <cylinder radius="0.05" length="0.05"/>

          </geometry>
      <surface>
        <friction>
          <fdir1>1 0 0</fdir1>
          <kp>1000000.0</kp> <!-- kp and kd for rubber -->
          <kd>100.0</kd>
          <mu>1</mu>
          <mu2>1</mu2>
          <slip1>0.5</slip1>
          <slip2>0</slip2>
        </friction>
      </surface>

      </collision>

  </link>



  <joint type="continuous" name="front_right_wheel_hinge">

    <origin xyz="0.1 -0.12 0" rpy="0 0 0"/>

    <child link="front_right_wheel"/>

    <parent link="chassis"/>

    <axis xyz="0 1 0" rpy="0 0 0"/>

    <limit effort="10000" velocity="1000"/>

    <dynamics damping="1.0" friction="1.0"/>

  </joint>



  <link name="back_right_wheel">

      <inertial>

          <origin xyz="0.0 0.0 0.0" rpy="0.0 1.5707 1.5707"/>

          <mass value="4.0"/>

          <inertia ixx="0.1" ixy="0.0" ixz="0.0" iyy="0.1" iyz="0.0" izz="0.1"/>

      </inertial>

      <visual name="bsck_right_wheel_visual">

          <origin xyz="0.0 0.0 0.0" rpy="0.0 1.5707 1.5707"/>

          <geometry>

              <cylinder radius="0.05" length="0.05"/>

          </geometry>

      </visual>

      <collision>

          <origin xyz="0.0 0.0 0.0" rpy="0.0 1.5707 1.5707"/>

          <geometry>

              <cylinder radius="0.05" length="0.05"/>

          </geometry>
          
      <surface>
        <friction>
          <fdir1>1 0 0</fdir1>
          <kp>1000000.0</kp> <!-- kp and kd for rubber -->
          <kd>100.0</kd>
          <mu>1</mu>
          <mu2>1</mu2>
          <slip1>0.5</slip1>
          <slip2>0</slip2>
        </friction>
      </surface>

      </collision>

  </link>



  <joint type="continuous" name="back_right_wheel_hinge">

    <origin xyz="-0.1 -0.12 0" rpy="0 0 0"/>

    <child link="back_right_wheel"/>

    <parent link="chassis"/>

    <axis xyz="0 1 0" rpy="0 0 0"/>

    <limit effort="10000" velocity="1000"/>

    <dynamics damping="1.0" friction="1.0"/>

  </joint>
  
  <joint type="fixed" name="front_bumper_joint">

    <origin xyz=".15 0 0" rpy="0 0 0"/>

    <child link="front_bumper"/>

    <parent link="chassis"/>
    
  </joint>
  
    <link name="front_bumper">
      <inertial>
          <origin xyz="0.0 0.0 0.0" rpy="0.0 0.0 0.0"/>
          <mass value="0.3"/>
          <inertia ixx="0.1" ixy="0.0" ixz="0.0" iyy="0.1" iyz="0.0" izz="0.1"/>
      </inertial>
      <visual name="front_bumper_visual">
          <origin xyz="0.0 0.0 0.0" rpy="1.5707 0.0 0.0"/>
          <geometry>
              <cylinder radius="0.025" length="0.15"/>
          </geometry>
      </visual>
      <collision>
          <origin xyz="0.0 0.0 0.0" rpy="1.5707 0.0 0.0"/>
          <geometry>
              <cylinder radius="0.025" length="0.15"/>
          </geometry>
      </collision>
  </link>
  
    <joint type="fixed" name="back_bumper_joint">

    <origin xyz="-.15 0 0" rpy="0 0 0"/>

    <child link="back_bumper"/>

    <parent link="chassis"/>
    
  </joint>
  
    <link name="back_bumper">
      <inertial>
          <origin xyz="0.0 0.0 0.0" rpy="0.0 0.0 0.0"/>
          <mass value="0.3"/>
          <inertia ixx="0.1" ixy="0.0" ixz="0.0" iyy="0.1" iyz="0.0" izz="0.1"/>
      </inertial>
      <visual name="back_bumper_visual">
          <origin xyz="0.0 0.0 0.0" rpy="1.5707 0.0 0.0"/>
          <geometry>
              <cylinder radius="0.025" length="0.15"/>
          </geometry>
      </visual>
      <collision>
          <origin xyz="0.0 0.0 0.0" rpy="1.5707 0.0 0.0"/>
          <geometry>
              <cylinder radius="0.025" length="0.15"/>
          </geometry>
      </collision>
  </link>

  <link name="sensor_holder">
      <inertial>
          <origin xyz="0.0 0.0 0.0" rpy="0.0 0.0 0.0"/>
          <mass value="3"/>
          <inertia ixx="0.1" ixy="0.0" ixz="0.0" iyy="0.1" iyz="0.0" izz="0.1"/>
      </inertial>
      <visual name="sensor_holder_visual">
          <origin xyz="0.0 0.0 0.0" rpy="0.0 0.0 0.0"/>
          <geometry>
              <box size="0.1 0.1 0.05"/>
          </geometry>
      </visual>
      <collision>
          <origin xyz="0.0 0.0 0.0" rpy="0.0 0.0 0.0"/>
          <geometry>
              <box size="0.1 0.1 0.05"/>
          </geometry>
      </collision>
  </link>

  <joint name="sensor_holder_joint" type="fixed">
      <origin xyz="0.0 0.0 0.05" rpy="0.0 0.0 0.0"/>
      <parent link="chassis"/>
      <child link="sensor_holder"/>
  </joint>

  <link name="camera">

      <inertial>

          <origin xyz="0.0 0.0 0.0" rpy="0.0 0.0 0.0"/>

          <mass value="0.1"/>

          <inertia ixx="1e-6" ixy="0.0" ixz="0.0" iyy="1e-6" iyz="0.0" izz="1e-6"/>

      </inertial>

      <visual name="">

          <origin xyz="0.0 0.0 0.0" rpy="0.0 0.0 0.0"/>

          <geometry>

              <box size="0.03 0.05 0.05"/>

          </geometry>

      </visual>

      <collision>

          <origin xyz="0.0 0.0 0.0" rpy="0.0 0.0 0.0"/>

          <geometry>

              <box size="0.03 0.05 0.05"/>

          </geometry>

      </collision>

  </link>



  <joint name="camera_joint" type="fixed">

      <origin xyz="0.07 0.0 0.0" rpy="0.0 0.0 0.0"/>

      <parent link="sensor_holder"/>

      <child link="camera"/>

  </joint>



  <link name="hokuyo">

      <inertial>

          <origin xyz="0.0 0.0 0.0" rpy="0.0 0.0 0.0"/>

          <mass value="0.1"/>

          <inertia ixx="1e-6" ixy="0.0" ixz="0.0" iyy="1e-6" iyz="0.0" izz="1e-6"/>

      </inertial>

      <visual name="hokuyo_visual">

          <origin xyz="0.0 0.0 0.0" rpy="0.0 0.0 0.0"/>

          <geometry>

              <mesh filename="package://where_am_i/meshes/hokuyo.dae" />

          </geometry>

      </visual>

      <collision>

          <origin xyz="0.0 0.0 0.0" rpy="0.0 0.0 0.0"/>

          <geometry>

              <box size="0.1 0.1 0.1"/>

          </geometry>

      </collision>

  </link>



  <joint name="hokuyo_joint" type="fixed">

      <origin xyz="0.0 0.0 0.075" rpy="0.0 0.0 0.0"/>

      <parent link="sensor_holder"/>

      <child link="hokuyo"/>

  </joint>



  </robot>